Workbook

Sheet Geral
A1: Demanda | B1: Qtd Horas | C1: Observação
A2: Release de Bandeiras
A3: Release de Bandeira Q1 e Q2/25 | B3: 500 | C3: Normalmente é estimado um valor fixo. Verificar com Marcinha qual a quantidade de horas que normalmente é estimada.
A4: Pré Autorização - Decurso de prazo | B4: 120 | C4: Vai depender do andamento da sprint 4 A principio estou estimando 1 sprint
A6: DMC
A7: Chargeback (ESTM1) | B7: =ESTM1!C9 -> 336
A8: Pré-Autorização | B8: 360 | C8: Precisa de uma Oportunidade / Refinamento para definir a solução para que seja possível levantar o esforço. A principio estou estimando 3 sprints, sendo 1 para definir solução + refinamento e 2 para iniciar desenvolvimento
A10: Modernização Master
A11: Modernização Transações Administrativas | B11: 40 | C11: O desenvolvimento será iniciado na sprint 4. Estou reservando 40 horas, prevendo transbordo.
A13: Débito Técnico
A14: Tratamento de registros base 2 sem base 1 | B14: 80 | C14: Gap atual da Conciliação de transações, gerando falta de visão e possível diferença contábil
A15: Aumentar Resiliência do Conciliação Débito | B15: 120 | C15: Pré requisito para migrar Conciliação do arquivo T464
A16: Migrar Conciliação do arquivo T464 para Conciliação Débito | B16: 80 | C16: Necessário para Desativação do antigo Conciliação, gerando redução de custo
A17: Tratar decurso de prazo de transações a partir da tabela de transações | B17: 160 | C17: Necessário para Desativação do antigo Conciliação, gerando redução de custo
A19: Camada Zero
A20: Unificação dos autorizadores - Lavantamento dos impactos | B20: 120 | C20: Mapeamento dos impactos (eventos x consumidores, etc), definição da solução e Refinamento
A21: Migrar ACL Autenticação no Segurança (ESTM2) | B21: =ESTM2!C8 -> 344 | C21: Pré requisito Camada Zero / Simplificação e Evolução da plataforma
A22: Desativar micro-serviço Fraudes Bandeiras (ESTM3) | B22: =ESTM3!C6 -> 120 | C22: Pré requisito Camada Zero / Simplificação e Evolução da plataforma Necessário puxar discovery com time AQ5 Sinergia com a frente Dados
A23: Documentação | B23: ? | C23: ver com Mateus
A24: Criação da conta aws | B24: ? | C24: ver com Mateus
A26: Dados
A27: Suporte TO2 | B27: ? | C27: Ver com Nishi
A28: Levar dados para Mesh | B28: =ESTM4!C5 -> 200
A30: Modernização Visa
A31: Tratar TC 05 após tratamento de decurso de prazo | B31: 80 | C31: Gap da plataforma modernizada
A33: Demanda Regulatória
A34: Finalizar Desenvolvimento | B34: 120 | C34: Vai depender do andamento da sprint 4 A principio estou estimando 1 sprint
A35: Carga | B35: ? | C35: Ver com Thiago
A38: Direciona Tech
A39: Datadog ? | B39: ?
A40: Necessário aguardar direcionamento do Cores | B40: ?
A42: Modernização Conciliação - Serviço Conciliação Contábil De Cartão Débito
A43: WA PAY Visa - Desativação | B43: 40
A44: Chargeback Single Message | B44: 120 | C44: Necssário alinhar com o time da Operação / Backoffice que o Chargeback será processado em D+1
A46: Conexão direta com a Master
A47: Projeto multiconexão
A49: Motivo de erro Interno (ESTM5)
A50: Pavimentação | B50: =ESTM5!C3 -> 120
A51: Implementar Cenário 1 - Erro gerado COM ocorrência X0 | B51: =ESTM5!C11 -> 166
A52: Implementar Cenário 2 - Erro gerado SEM ocorrência X0 - Retorno Segurança | B52: =ESTM5!C16 -> 122
...

Sheet ESTM1
A1: Estimativa Chargeback DMC
A2: Task | B2: Componente | C2: Horas | G2: Desenho de solução
A3: Refinamentos | C3: 24
A4: Criar rotina para formatar arquivo TG52 no padrão Lambda | B4: Mainframe | C4: 16
A5: Criar rotina para transmitir arquivo TG52 para o bucket S3 | B5: Mainframe | C5: 16
A6: Criar lambda para consistir arquivo TG52 | B6: Lambda | C6: 80
A7: Desenvolver Parse de registros TG52 | B7: Formatador Contábil | C7: 80
A8: Criar produto no Conciliação Débito para fazer lançamento | B8: Conciliação Débito | C8: 120
C9: =SUM(C3:C8) -> 336

Sheet ESTM2
A1: Migrar ACL Autenticação no Segurança
A2: Task | B2: Componente | C2: Horas | G2: Desenho de solução
A3: Refinamentos | C3: 24
A4: Adaptar Autorizador Digital para usar o Segurança para validar autenticação 3DS | B4: aws - Autorizador Digital | C4: 60
A5: Incluir função para validação de autenticação 3DS | B5: aws - ACL Segurança | C5: 80
A6: Alterar transação CR1 para se integrar com a transação 3DS para função de autenticação 3DS | B6: Mainframe - CR1 | C6: 90
A7: Alterar transação 3DS para se integrar com a transação CR1 para função de autenticação 3DS | B7: Mainframe - 3DS | C7: 90
C8: =SUM(C3:C7) -> 344

Sheet ESTM3
A1: Desativar micro-serviço Fraudes Bandeiras - Gravar transações advice mastercard no mesh
A2: Task | B2: Componente | C2: Horas | G2: Desenho de solução
A3: Levantar campos que existem no contrato atual com Fraudes e não existe no transação finalizada | C3: 16
A4: Alterar Formatador para direcionar transação de advice Mastercard para o Autorizador Presente | B4: aws - Formatador | C4: 80
A5: Validação e Testes do Autorizador Presente | B5: aws - Autorizador Presente | C5: 24
C6: =SUM(C3:C5) -> 120

Sheet ESTM4
A1: Desativar micro-serviço Fraudes Bandeiras - Gravar transações advice mastercard no mesh
A2: Task | B2: Componente | C2: Horas | G2: Desenho de solução
A3: Alterar Formatador para direcionar todas as transações para o Autorizador | B3: aws - Formatador | C3: 80
A4: Criar produto(s) para tratar as transações direcionadas pelo Formatador | B4: aws - Autorizador Presente | C4: 120
C5: =SUM(C3:C4) -> 200

Sheet ESTM5
A1: Desativar micro-serviço Fraudes Bandeiras - Gravar transações advice mastercard no mesh
A2: Task | B2: Componente | C2: Horas | G2: Desenho de solução
A3: Pavimentação | C3: =SUM(C4:C9) -> 120
A4: Incluir campo no evento Transação Finalizada e Conciliação Finalizada | C4: 16
A5: Mapeamento do campo no Autorizadores | C5: 24
A6: Incluir campo nas tabelas Data Mesh | C6: 8
A7: Alterar Glue Job | C7: 24
A8: Incluir Campo na Tabela de Transações | C8: 24
A9: Incluir campo no response da API | C9: 24
A11: Implementar Cenário 1 - Erro gerado COM ocorrência X0 | C11: =SUM(C12:C14) -> 166
A12: Realizar mapeamento / engenharia reversa das ocorrências X0 retornadas pelos serviços Contas, Limite operacional e Limite Portador | B12: Mainframe | C12: 60
A13: Desenvolver De Para: Ocorrência X0 x Motivo Interno mapeando para o novo campo de motivo de erro interno | B13: Autorizador | C13: 90
A14: Correlacionar as ocorrências X0 com os códigos de motivo do Autorizador de Crédito | B14: n/a | C14: 16
A16: Implementar Cenário 2 - Erro gerado SEM ocorrência X0 - Retorno Segurança | C16: =SUM(C17:C19) -> 122
A17: Mapeamento dos erros retornados pelo Segurança | B17: n/a | C17: 16
A18: Criar interpretador do retorno do serviço de Segurança para montar o código de erro Interno para o novo campo de motivo de erro interno | B18: Autorizador | C18: 90
A19: Correlacionar as ocorrências X0 com os códigos de motivo do Autorizador de Crédito | B19: n/a | C19: 16
A21: Implementar Cenário 2 - Erro gerado SEM ocorrência X0 - BC, AQ5, CC | C21: =SUM(C22:C24) -> 104
A22: Mapeamento dos erros retornados pelos serviços das siglas BC, AQ5 e CC | B22: n/a | C22: 16
A23: Criar interpretador do retorno dos serviços das siglas BC, AQ5 e CC para montar o código de erro Interno para o novo campo de motivo de erro interno | B23: Autorizador | C23: 80
A24: Correlacionar as ocorrências X0 com os códigos de motivo do Autorizador de Crédito | B24: n/a | C24: 8
A26: Implementar Cenário 2 - Erro gerado SEM ocorrência X0 - Demais Serviços | C26: =SUM(C27:C29) -> 104
A27: Mapeamento dos erros retornados pelos demais serviços | B27: n/a | C27: 16
A28: Criar interpretador do retorno dos demais serviços para montar o código de erro Interno para o novo campo de motivo de erro interno | B28: Autorizador | C28: 80
A29: Correlacionar as ocorrências X0 com os códigos de motivo do Autorizador de Crédito | B29: n/a | C29: 8
A31: Implementar Cenário 3 - Erro gerado no próprio Autorizador | C31: =SUM(C32:C34) -> 128
A32: Mapeamento dos erros gerado pelo Autorizador | B32: n/a | C32: 40
A33: Ajustar Error Handler para tratar o novo campo código motivo erro interno | B33: Autorizador | C33: 80
A34: Correlacionar as ocorrências X0 com os códigos de motivo do Autorizador de Crédito | B34: n/a | C34: 8
A36: Implementar Cenário 4 - Erro gerado no Conciliação | C36: =SUM(C37:C39) -> 128
A37: Mapeamento dos erros gerado pelo Conciliação | B37: n/a | C37: 40
A38: Ajustar Error Handler para tratar o novo campo código motivo erro interno | B38: Autorizador | C38: 80
A39: Correlacionar as ocorrências X0 com os códigos de motivo do Autorizador de Crédito | B39: n/a | C39: 8
